<?xml version="1.0"?>
<robot  name="lwa4d">

	<link name="world" />


	<!-- L0 -->
	<link name="L0_link">
		<inertial>
				<origin xyz="0 0 0" rpy="0 0 0"/>
				<mass value="1.0"/>
				<inertia ixx="0.01" ixy="0" ixz="0" iyy="0.01" iyz="0" izz="0.01" />
			</inertial>
		</link>

	<!-- J0 -->
	<joint name="L0_joint" type="floating" >
   		<origin  rpy="0 0 0" xyz="0 0 0" />
		<parent link="world" />
		<child link="L0_link" />
	</joint>

	<!-- J1 -->
		<joint name="L1_joint" type="revolute">
			<origin xyz="0 -0.1375 0" rpy="-1.5708 3.1416 0"/>
			<parent link="L0_link"/>
			<child link="L1_link"/>
			<axis xyz="0 0 1"/>
			<dynamics damping="10" />
			<limit effort="370" velocity="2.0" lower="-6.2831853" upper="6.2831853"/>
		</joint>

	<!-- L1 -->
		<link name="L1_link">
			<inertial>
				<origin xyz="0 0 0" rpy="0 0 0" />
				<!--mass value="5.9907"/-->
				<mass value="2.0"/>
				<inertia ixx="0.01" ixy="0" ixz="0" iyy="0.01" iyz="0" izz="0.01" />
			</inertial>
			
			<visual>
				<origin xyz="0 0 0" rpy="0 0 0" />
				<geometry>
					<mesh filename="$(find ros_apc)/data/models/lwa4d/meshes/arm_1_link.dae" />
				</geometry>
				<material name="Schunk_LightGrey">
					<color rgba="0.7 0.7 0.7 1.0"/>
				</material>
			</visual>
			
			<collision>
				<origin xyz="0 0 0" rpy="0 0 0" />
				<geometry>
					<mesh filename="$(find ros_apc)/data/models/lwa4d/meshes/arm_1_link.dae" />
				</geometry>
			</collision>
		</link>

	<!-- J2 -->
		<joint name="L2_joint" type="revolute">
			<origin xyz="0 0 -0.18" rpy="-1.57 0 0"/>
			<parent link="L1_link"/>
			<child link="L2_link"/>
			<axis xyz="0 0 1"/>
			<dynamics damping="10" />
			<limit effort="370" velocity="2.0" lower="-1.97" upper="1.97"/>
		</joint>

		<!-- L2 -->
		<link name="L2_link">
			<inertial>
				<origin xyz="0 0 0" rpy="0 0 0"/>
				<mass value="2.0"/>
				<inertia ixx="0.03" ixy="0" ixz="0" iyy="0.03" iyz="0" izz="0.03" />
			</inertial>
			
			<visual>
				<origin xyz="0 0 0" rpy="0 0 0" />
				<geometry>
					<mesh filename="$(find ros_apc)/data/models/lwa4d/meshes/arm_2_link.dae" />
				</geometry>
				<material name="Schunk_Black" />
			</visual>
			
			<collision>
				<origin xyz="0 0 0" rpy="0 0 0" />
				<geometry>
					<mesh filename="$(find ros_apc)/data/models/lwa4d/meshes/arm_2_link.dae"/>
				</geometry>
			</collision>
		</link>

		<!-- J3-->	
		<joint name="L3_joint" type="revolute">
			<origin xyz="0 0 0" rpy="1.57 0 0"/>
			<parent link="L2_link"/>
			<child link="L3_link"/>
			<axis xyz="0 0 1"/>
			<dynamics damping="5" />
			<limit effort="176" velocity="2.0" lower="-6.2831853" upper="6.2831853"/>
		</joint>

		<!-- L3 -->
		<link name="L3_link">
			<inertial>
				<origin xyz="0 0 0" rpy="0 0 0"/>
				<mass value="2.0"/>
				<inertia ixx="0.03" ixy="0" ixz="0" iyy="0.03" iyz="0" izz="0.03" />
			</inertial>
			
			<visual>
				<origin xyz="0 0 0" rpy="0 0 0" />
				<geometry>
					<mesh filename="$(find ros_apc)/data/models/lwa4d/meshes/arm_3_link.dae" />
				</geometry>
				<material name="Schunk_LightGrey" />
			</visual>
			
			<collision>
				<origin xyz="0 0 0" rpy="0 0 0" />
				<geometry>
					<mesh filename="$(find ros_apc)/data/models/lwa4d/meshes/arm_3_link.dae"/>
				</geometry>
			</collision>
		</link>	

		<!-- J4 -->
		<joint name="L4_joint" type="revolute">
			<origin xyz="0 0 -0.328" rpy="-1.57 0 0"/>
			<parent link="L3_link"/>
			<child link="L4_link"/>
			<axis xyz="0 0 1" />
			<dynamics damping="5" />
			<limit effort="176" velocity="2.0" lower="-2.08208" upper="2.08208"/>
		</joint>

		<!-- L4 -->  
		<link name="L4_link">
			<inertial>
				<origin xyz="0 0 0" rpy="0 0 0"/>
				<mass value="2.0"/>
				<inertia ixx="0.03" ixy="0" ixz="0" iyy="0.03" iyz="0" izz="0.03" />
			</inertial>
			
			<visual>
				<origin xyz="0 0 0" rpy="0 0 0" />
				<geometry>
					<mesh filename="$(find ros_apc)/data/models/lwa4d/meshes/arm_4_link.dae" />
				</geometry>
				<material name="Schunk_Black" />
			</visual>
			
			<collision>
				<origin xyz="0 0 0" rpy="0 0 0" />
				<geometry>
					<mesh filename="$(find ros_apc)/data/models/lwa4d/meshes/arm_4_link.dae"/>
				</geometry>
			</collision>
		</link>

		<!-- J5 -->
		<joint name="L5_joint" type="revolute">
			<origin xyz="0 0 0" rpy="1.57 0 0" />
			<parent link="L4_link"/>
			<child link="L5_link"/>
			<axis xyz="0 0 1" />
			<dynamics damping="5" />
			<limit effort="41.6" velocity="2.0" lower="-6.2831853" upper="6.2831853" />
		</joint>

		<!-- L5 -->
		<link name="L5_link">
			<inertial>
				<origin xyz="0 0 0" rpy="0 0 0"/>
				<mass value="2.313272"/>
				<inertia ixx="0.03" ixy="0" ixz="0" iyy="0.03" iyz="0" izz="0.03" />
			</inertial>
			
			<visual>
				<origin xyz="0 0 0" rpy="0 0 0" />
				<geometry>
					<mesh filename="$(find ros_apc)/data/models/lwa4d/meshes/arm_5_link.dae" />
				</geometry>
				<material name="Schunk_LightGrey" />
			</visual>
			
			<collision>
				<origin xyz="0 0 0" rpy="0 0 0" />
				<geometry>
					<mesh filename="$(find ros_apc)/data/models/lwa4d/meshes/arm_5_link.dae"/>
				</geometry>
			</collision>
		</link>

		<!-- J6 -->
		<joint name="L6_joint" type="revolute">
			<origin xyz="0 0 -0.323" rpy="1.57 0 0" />
			<parent link="L5_link"/>
			<child link="L6_link"/>
			<axis xyz="0 0 1" />
			<dynamics damping="5" />
			<limit effort="20.1" velocity="2.0" lower="-1.8" upper="1.8" />
		</joint>

		<!-- L6 -->
		<link name="L6_link">
			<inertial>
				<origin xyz="0 0 0" rpy="0 0 0"/>
				<mass value="2.057856"/>
				<inertia ixx="0.01" ixy="0" ixz="0" iyy="0.01" iyz="0" izz="0.01" />
			</inertial>
			
			<visual>
				<origin xyz="0 0 0" rpy="0 0 0" />
				<geometry>
					<mesh filename="$(find ros_apc)/data/models/lwa4d/meshes/arm_6_link.dae" />
				</geometry>
				<material name="Schunk_Black" />
			</visual>
			
			<collision>
				<origin xyz="0 0 0" rpy="0 0 0" />
				<geometry>
					<mesh filename="$(find ros_apc)/data/models/lwa4d/meshes/arm_6_link.dae"/>
				</geometry>
			</collision>
		</link>

		<!-- J7-->
		<joint name="L7_joint" type="revolute">
			<origin xyz="0 -0.075 0" rpy="-1.57 0 0" />
			<parent link="L6_link"/>
			<child link="L7_link"/>
			<axis xyz="0 0 1" />
			<dynamics damping="5" />
			<limit effort="9.6" velocity="2.0" lower="-6.2831853" upper="6.2831853" />
		</joint>

		<!-- L7-->
		<link name="L7_link">
			<inertial>
				<origin xyz="0 0 0" rpy="0 0 0"/>
				<mass value="1.120198"/>
				<inertia ixx="0.01" ixy="0" ixz="0" iyy="0.01" iyz="0" izz="0.01" />
			</inertial>
			
			<visual>
				<origin xyz="0 0 0" rpy="0 0 0" />
				<geometry>
					<mesh filename="$(find ros_apc)/data/models/lwa4d/meshes/arm_7_link.dae" />
				</geometry>
				<material name="Schunk_LightGrey" />
			</visual>
			
			<collision>
				<origin xyz="0 0 0" rpy="0 0 0" />
				<geometry>
					<mesh filename="$(find ros_apc)/data/models/lwa4d/meshes/arm_7_link.dae"/>
				</geometry>
			</collision>
		</link>


</robot>
