<?xml version="1.0"?>
<robot name="sdh" >

<link name="world" />

		<!-- joint between arm_7_link and sdh_palm_link -->
		<joint name="palm_joint" type="floating" >
			<origin xyz="0 0 0" rpy="0 0 0"/>
			<parent link="world" />
			<child link="palm_link" />
		</joint>

		<link name="palm_link">
			<inertial>
				<origin xyz="0 0 0" rpy="0 0 0"/>
				<mass value="1"/>
				<inertia ixx="0.01" ixy="0" ixz="0" iyy="0.01" iyz="0" izz="0.01" />
			</inertial>
			
			<visual>
				<origin xyz="0 0 0" rpy="0 0 0" />
				<geometry>
					<mesh filename="$(find apc_ros)/data/models/sdh/meshes/palm.dae" />
				</geometry>
				<material name="Schunk_LightGrey">
					<color rgba="0.7 0.7 0.7 1.0"/>
				</material>
			</visual>
			
			<collision>
				<origin xyz="0 0 0" rpy="0 0 0" />
				<geometry>
					<mesh filename="$(find apc_ros)/data/models/sdh/meshes/palm.dae"/>
				</geometry>
			</collision>
		</link>
		
		<!-- grasp link -->
		<joint name="grasp_joint" type="fixed" >
			<origin xyz="0 0 0.15" rpy="0 0 0"/>
			<parent link="palm_link" />
			<child link="grasp_link" />
		</joint>

		<link name="grasp_link"/>

		<!-- tip link -->
		<joint name="tip_joint" type="fixed" >
			<origin xyz="0 0 0.22" rpy="0 0 0"/>
			<parent link="palm_link" />
			<child link="tip_link" />
		</joint>

		<link name="tip_link"/>

		<!-- finger1 -->
		<!-- joint between sdh_palm_link and sdh_finger_11_link -->
		<joint name="knuckle_joint" type="revolute">
			<origin xyz="0.033 -0.01905 0.0745" rpy="0 0 1.5708" />
			<parent link="palm_link"/>
			<child link="finger_11_link"/>
			<axis xyz="0 0 1" />
			<dynamics damping="1" />
			<limit effort="100" lower="0" upper="1.570796327" velocity="5"/>
		</joint>

		<link name="finger_11_link">
			<inertial>
				<origin xyz="0 0 0" rpy="0 0 0"/>
				<mass value="0.1"/>
				<inertia ixx="0.01" ixy="0" ixz="0" iyy="0.01" iyz="0" izz="0.01" />
			</inertial>
			
			<visual>
				<origin xyz="0 0 0" rpy="0 0 0" />
				<geometry>
					<mesh filename="$(find apc_ros)/data/models/sdh/meshes/knuckle.dae" />
				</geometry>
				<material name="Schunk_LightGrey" />
			</visual>
			
			<collision>
				<origin xyz="0 0 0" rpy="0 0 0" />
				<geometry>
				<mesh filename="$(find apc_ros)/data/models/sdh/meshes/knuckle.dae"/>
				</geometry>
			</collision>
		</link>

		<!-- joint between sdh_finger_11_link and sdh_finger_12_link -->
		<joint name="finger_12_joint" type="revolute">
			<origin xyz="0 0 0.0165" rpy="0 0 0" />
			<parent link="finger_11_link"/>
			<child link="finger_12_link"/>
			<axis xyz="0 1 0" />
			<dynamics damping="1" />
			<limit effort="100" lower="-1.570796327" upper="1.570796327" velocity="5"/>
		</joint>

		<link name="finger_12_link">
			<inertial>
				<origin xyz="0 0 0" rpy="0 0 0"/>
				<mass value="0.1"/>
				<inertia ixx="0.01" ixy="0" ixz="0" iyy="0.01" iyz="0" izz="0.01" />
			</inertial>
			
			<visual>
				<origin xyz="0 0 0" rpy="0 0 0" />
				<geometry>
					<mesh filename="$(find apc_ros)/data/models/sdh/meshes/finger.dae" />
				</geometry>
			<material name="Schunk_LightGrey" />
			</visual>
			
			<collision>
				<origin xyz="0 0 0" rpy="0 0 0" />
				<geometry>
					<mesh filename="$(find apc_ros)/data/models/sdh/meshes/finger.dae"/>
				</geometry>
			</collision>
		</link>

		<!-- joint between sdh_finger_12_link and sdh_finger_13_link -->
		<joint name="finger_13_joint" type="revolute">
			 
			<origin xyz="0 0 0.0865" rpy="0 0 0" />
			<parent link="finger_12_link"/>
			<child link="finger_13_link"/>
			<axis xyz="0 1 0" />
			<dynamics damping="1" />
			<limit effort="100" lower="-1.570796327" upper="1.570796327" velocity="5"/>
		</joint>

		<link name="finger_13_link">
			<inertial>
			<origin xyz="0 0 0" rpy="0 0 0"/>
				<mass value="0.1"/>
				<inertia ixx="0.01" ixy="0" ixz="0" iyy="0.01" iyz="0" izz="0.01" />
			</inertial>
			
			<visual>
				<origin xyz="0 0 0" rpy="0 0 0" />
				<geometry>
					<mesh filename="$(find apc_ros)/data/models/sdh/meshes/finger_tip.dae" />
				</geometry>
				<material name="Schunk_LightGrey" />
			</visual>
			
			<collision>
				<origin xyz="0 0 0" rpy="0 0 0" />
				<geometry>
					<mesh filename="$(find apc_ros)/data/models/sdh/meshes/finger_tip.dae"/>
				</geometry>
			</collision>
		</link>

		<!-- finger2 -->
		<!-- joint between sdh_palm_link and sdh_finger_21_link -->
		<joint name="finger_21_joint" type="revolute">
			<mimic joint="knuckle_joint" multiplier="1" offset="0"/>
			<origin xyz="-0.033 -0.01905 0.0745" rpy="0 0 1.5708" />
			<parent link="palm_link"/>
			<child link="finger_21_link"/>
			<axis xyz="0 0 -1" />
			<dynamics damping="1" />
			<limit effort="100" lower="0" upper="1.570796327" velocity="5"/>
		</joint>

		<link name="finger_21_link">
			<inertial>
				<origin xyz="0 0 0" rpy="0 0 0"/>
				<mass value="0.1"/>
				<inertia ixx="0.01" ixy="0" ixz="0" iyy="0.01" iyz="0" izz="0.01" />
			</inertial>
			
			<visual>
				<origin xyz="0 0 0" rpy="0 0 0" />
				<geometry>
					<mesh filename="$(find apc_ros)/data/models/sdh/meshes/knuckle.dae" />
				</geometry>
				<material name="Schunk_LightGrey" />
			</visual>
			
			<collision>
				<origin xyz="0 0 0" rpy="0 0 0" />
				<geometry>
					<mesh filename="$(find apc_ros)/data/models/sdh/meshes/knuckle.dae"/>
				</geometry>
			</collision>
		</link>

		<!-- joint between sdh_finger_21_link and sdh_finger_22_link -->
		<joint name="finger_22_joint" type="revolute">
			<origin xyz="0 0 0.0165" rpy="0 0 0" />
			<parent link="finger_21_link"/>
			<child link="finger_22_link"/>
			<axis xyz="0 1 0" />
			<dynamics damping="1" />
			<limit effort="100" lower="-1.570796327" upper="1.570796327" velocity="5"/>
		</joint>

		<link name="finger_22_link">
			<inertial>
				<origin xyz="0 0 0" rpy="0 0 0"/>
				<mass value="0.1"/>
				<inertia ixx="0.01" ixy="0" ixz="0" iyy="0.01" iyz="0" izz="0.01" />
			</inertial>
			
			<visual>
				<origin xyz="0 0 0" rpy="0 0 0" />
				<geometry>
					<mesh filename="$(find apc_ros)/data/models/sdh/meshes/finger.dae" />
				</geometry>
				<material name="Schunk_LightGrey" />
			</visual>
			
			<collision>
				<origin xyz="0 0 0" rpy="0 0 0" />
				<geometry>
					<mesh filename="$(find apc_ros)/data/models/sdh/meshes/finger.dae"/>
				</geometry>
			</collision>
		</link>

		<!-- joint between sdh_finger_22_link and sdh_finger_23_link -->
		<joint name="finger_23_joint" type="revolute">
			<origin xyz="0 0 0.0865" rpy="0 0 0" />
			<parent link="finger_22_link"/>
			<child link="finger_23_link"/>
			<axis xyz="0 1 0" />
			<dynamics damping="1" />
			<limit effort="100" lower="-1.570796327" upper="1.570796327" velocity="5"/>
		</joint>

		<link name="finger_23_link">
			<inertial>
				<origin xyz="0 0 0" rpy="0 0 0"/>
				<mass value="0.1"/>
				<inertia ixx="0.01" ixy="0" ixz="0" iyy="0.01" iyz="0" izz="0.01" />
			</inertial>
			
			<visual>
				<origin xyz="0 0 0" rpy="0 0 0" />
				<geometry>
					<mesh filename="$(find apc_ros)/data/models/sdh/meshes/finger_tip.dae" />
				</geometry>
				<material name="Schunk_LightGrey" />
			</visual>
			
			<collision>
				<origin xyz="0 0 0" rpy="0 0 0" />
				<geometry>
					<mesh filename="$(find apc_ros)/data/models/sdh/meshes/finger_tip.dae"/>
				</geometry>
			</collision>
		</link>

		<!-- thumb -->
		<!-- joint between sdh_palm_link and sdh_thumb_1_link -->
		<joint name="thumb_1_joint" type="fixed">
			<origin xyz="0 0.03811 0.0745 " rpy="0 0 -1.5708" />
			<parent link="palm_link"/>
			<child link="thumb_1_link"/>
		</joint>

		<link name="thumb_1_link">
			<inertial>
				<origin xyz="0 0 0" rpy="0 0 0"/>
				<mass value="0.1"/>
				<inertia ixx="0.01" ixy="0" ixz="0" iyy="0.01" iyz="0" izz="0.01" />
			</inertial>
			
			<visual>
				<origin xyz="0 0 0" rpy="0 0 0" />
				<geometry>
					<mesh filename="$(find apc_ros)/data/models/sdh/meshes/knuckle.dae" />
				</geometry>
				<material name="Schunk_LightGrey" />
			</visual>
			
			<collision>
				<origin xyz="0 0 0" rpy="0 0 0" />
				<geometry>
					<mesh filename="$(find apc_ros)/data/models/sdh/meshes/knuckle.dae"/>
				</geometry>
			</collision>
		</link>

		<!-- joint between sdh_thumb_1_link and shd_thumb_2_link -->
		<joint name="thumb_2_joint" type="revolute">
		<origin xyz="0 0 0.0165" rpy="0 0 0" />
		<parent link="thumb_1_link"/>
		<child link="thumb_2_link"/>
		<axis xyz="0 1 0" />
		<dynamics damping="1" />
		<limit effort="100" lower="-1.570796327" upper="1.570796327" velocity="5"/>
		</joint>

		<link name="thumb_2_link">
			<inertial>
				<origin xyz="0 0 0" rpy="0 0 0"/>
				<mass value="0.1"/>	
				<inertia ixx="0.01" ixy="0" ixz="0" iyy="0.01" iyz="0" izz="0.01" />
			</inertial>
		
			<visual>
				<origin xyz="0 0 0" rpy="0 0 0" />
				<geometry>
					<mesh filename="$(find apc_ros)/data/models/sdh/meshes/finger.dae" />
				</geometry>
				<material name="Schunk_LightGrey" />
			</visual>
		
			<collision>
				<origin xyz="0 0 0" rpy="0 0 0" />
				<geometry>
					<mesh filename="$(find apc_ros)/data/models/sdh/meshes/finger.dae"/>
				</geometry>
			</collision>
		</link>

		<!-- joint between sdh_thumb_2_link and sdh_thumb_3_link -->
		<joint name="thumb_3_joint" type="revolute">
			<origin xyz="0 0 0.0865" rpy="0 0 0" />
			<parent link="thumb_2_link"/>
			<child link="thumb_3_link"/>
			<axis xyz="0 1 0" />
			<dynamics damping="1" />
			<limit effort="100" lower="-1.570796327" upper="1.570796327" velocity="5"/>
		</joint>

		<link name="thumb_3_link">
			<inertial>
				<origin xyz="0 0 0" rpy="0 0 0"/>
				<mass value="0.1"/>
				<inertia ixx="0.01" ixy="0" ixz="0" iyy="0.01" iyz="0" izz="0.01" />
			</inertial>
			
			<visual>
				<origin xyz="0 0 0" rpy="0 0 0" />
				<geometry>
					<mesh filename="$(find apc_ros)/data/models/sdh/meshes/finger_tip.dae" />
				</geometry>
				<material name="Schunk_LightGrey" />
			</visual>
			
			<collision>
				<origin xyz="0 0 0" rpy="0 0 0" />
				<geometry>
					<mesh filename="$(find apc_ros)/data/models/sdh/meshes/finger_tip.dae"/>
				</geometry>
			</collision>
		</link>
	

</robot>
