<?xml version="1.0"?>
<robot  name="lwa4d">

	<link name="world" />

	<!-- J0 -->
	<joint name="L0_joint" type="fixed" >
   		<origin  rpy="0 0 0" xyz="0 0 0" />
		<parent link="world" />
		<child link="L0_link" />
	</joint>

	<!-- L0 -->
	<link name="L0_link">
		<inertial>
				<origin xyz="0 0 0" rpy="0 0 0"/>
				<mass value="1.0"/>
				<inertia ixx="0.01" ixy="0" ixz="0" iyy="0.01" iyz="0" izz="0.01" />
			</inertial>

			<visual>
				<origin xyz="0 0 0.004" rpy="0 0 0" />
				<geometry>
					<cylinder radius="0.045" length="0.08"/>
				</geometry>
				<material name="Schunk_LightGrey">
					<color rgba="0.7 0.7 0.7 1.0"/>
				</material>
			</visual>

			<collision>
				<origin xyz="0 0 0.005" rpy="0 0 0" />
				<geometry>
					<box size="0.01 0.01 0.01"/>
				</geometry>
			</collision>
		</link>

	<!-- J1 -->
		<joint name="L1_joint" type="revolute">
			<origin xyz="0 0 0.1" rpy="0 -3.1416 0"/>
			<parent link="L0_link"/>
			<child link="L1_link"/>
			<axis xyz="0 0 1"/>
			<dynamics damping="10" />
			<limit effort="370" velocity="2.0" lower="-6.2831853" upper="6.2831853"/>
		</joint>

	<!-- L1 -->
		<link name="L1_link">
			<inertial>
				<origin xyz="0 0 0" rpy="0 0 0" />
				<!--mass value="5.9907"/-->
				<mass value="2.0"/>
				<inertia ixx="0.01" ixy="0" ixz="0" iyy="0.01" iyz="0" izz="0.01" />
			</inertial>
			
			<visual>
				<origin xyz="0 0 0" rpy="0 0 0" />
				<geometry>
					<mesh filename="package://apc_ros/data/models/lwa4d/meshes/arm_1_link.dae" />
				</geometry>
				<material name="Schunk_LightGrey">
					<color rgba="0.7 0.7 0.7 1.0"/>
				</material>
			</visual>
			
			<collision>
				<origin xyz="0 0 0" rpy="0 0 0" />
				<geometry>
					<mesh filename="package://apc_ros/data/models/lwa4d/meshes/arm_1_link.dae" />
				</geometry>
			</collision>
		</link>

	<!-- J2 -->
		<joint name="L2_joint" type="revolute">
			<origin xyz="0 0 -0.18" rpy="-1.57 0 0"/>
			<parent link="L1_link"/>
			<child link="L2_link"/>
			<axis xyz="0 0 1"/>
			<dynamics damping="10" />
			<limit effort="370" velocity="2.0" lower="-1.97" upper="1.97"/>
		</joint>

		<!-- L2 -->
		<link name="L2_link">
			<inertial>
				<origin xyz="0 0 0" rpy="0 0 0"/>
				<mass value="2.0"/>
				<inertia ixx="0.03" ixy="0" ixz="0" iyy="0.03" iyz="0" izz="0.03" />
			</inertial>
			
			<visual>
				<origin xyz="0 0 0" rpy="0 0 0" />
				<geometry>
					<mesh filename="package://apc_ros/data/models/lwa4d/meshes/arm_2_link.dae" />
				</geometry>
				<material name="Schunk_Black">
					<color rgba="0.0 0.0 0.0 1.0"/>
				</material>
			</visual>
			
			<collision>
				<origin xyz="0 0 0" rpy="0 0 0" />
				<geometry>
					<mesh filename="package://apc_ros/data/models/lwa4d/meshes/arm_2_link.dae"/>
				</geometry>
			</collision>
		</link>

		<!-- J3-->	
		<joint name="L3_joint" type="revolute">
			<origin xyz="0 0 0" rpy="1.57 0 0"/>
			<parent link="L2_link"/>
			<child link="L3_link"/>
			<axis xyz="0 0 1"/>
			<dynamics damping="5" />
			<limit effort="176" velocity="2.0" lower="-6.2831853" upper="6.2831853"/>
		</joint>

		<!-- L3 -->
		<link name="L3_link">
			<inertial>
				<origin xyz="0 0 0" rpy="0 0 0"/>
				<mass value="2.0"/>
				<inertia ixx="0.03" ixy="0" ixz="0" iyy="0.03" iyz="0" izz="0.03" />
			</inertial>
			
			<visual>
				<origin xyz="0 0 0" rpy="0 0 0" />
				<geometry>
					<mesh filename="package://apc_ros/data/models/lwa4d/meshes/arm_3_link.dae" />
				</geometry>
				<material name="Schunk_LightGrey" />
			</visual>
			
			<collision>
				<origin xyz="0 0 0" rpy="0 0 0" />
				<geometry>
					<mesh filename="package://apc_ros/data/models/lwa4d/meshes/arm_3_link.dae"/>
				</geometry>
			</collision>
		</link>	

		<!-- J4 -->
		<joint name="L4_joint" type="revolute">
			<origin xyz="0 0 -0.328" rpy="-1.57 0 0"/>
			<parent link="L3_link"/>
			<child link="L4_link"/>
			<axis xyz="0 0 1" />
			<dynamics damping="5" />
			<limit effort="176" velocity="2.0" lower="-2.08208" upper="2.08208"/>
		</joint>

		<!-- L4 -->  
		<link name="L4_link">
			<inertial>
				<origin xyz="0 0 0" rpy="0 0 0"/>
				<mass value="2.0"/>
				<inertia ixx="0.03" ixy="0" ixz="0" iyy="0.03" iyz="0" izz="0.03" />
			</inertial>
			
			<visual>
				<origin xyz="0 0 0" rpy="0 0 0" />
				<geometry>
					<mesh filename="package://apc_ros/data/models/lwa4d/meshes/arm_4_link.dae" />
				</geometry>
				<material name="Schunk_Black">
					<color rgba="0.0 0.0 0.0 1.0"/>
				</material>
			</visual>
			
			<collision>
				<origin xyz="0 0 0" rpy="0 0 0" />
				<geometry>
					<mesh filename="package://apc_ros/data/models/lwa4d/meshes/arm_4_link.dae"/>
				</geometry>
			</collision>
		</link>

		<!-- J5 -->
		<joint name="L5_joint" type="revolute">
			<origin xyz="0 0 0" rpy="1.57 0 0" />
			<parent link="L4_link"/>
			<child link="L5_link"/>
			<axis xyz="0 0 1" />
			<dynamics damping="5" />
			<limit effort="41.6" velocity="2.0" lower="-6.2831853" upper="6.2831853" />
		</joint>

		<!-- L5 -->
		<link name="L5_link">
			<inertial>
				<origin xyz="0 0 0" rpy="0 0 0"/>
				<mass value="2.313272"/>
				<inertia ixx="0.03" ixy="0" ixz="0" iyy="0.03" iyz="0" izz="0.03" />
			</inertial>
			
			<visual>
				<origin xyz="0 0 0" rpy="0 0 0" />
				<geometry>
					<mesh filename="package://apc_ros/data/models/lwa4d/meshes/arm_5_link.dae" />
				</geometry>
				<material name="Schunk_LightGrey" />
			</visual>
			
			<collision>
				<origin xyz="0 0 0" rpy="0 0 0" />
				<geometry>
					<mesh filename="package://apc_ros/data/models/lwa4d/meshes/arm_5_link.dae"/>
				</geometry>
			</collision>
		</link>

		<!-- J6 -->
		<joint name="L6_joint" type="revolute">
			<origin xyz="0 0 -0.323" rpy="1.57 0 0" />
			<parent link="L5_link"/>
			<child link="L6_link"/>
			<axis xyz="0 0 1" />
			<dynamics damping="5" />
			<limit effort="20.1" velocity="2.0" lower="-1.8" upper="1.8" />
		</joint>

		<!-- L6 -->
		<link name="L6_link">
			<inertial>
				<origin xyz="0 0 0" rpy="0 0 0"/>
				<mass value="2.057856"/>
				<inertia ixx="0.01" ixy="0" ixz="0" iyy="0.01" iyz="0" izz="0.01" />
			</inertial>
			
			<visual>
				<origin xyz="0 0 0" rpy="0 0 0" />
				<geometry>
					<mesh filename="package://apc_ros/data/models/lwa4d/meshes/arm_6_link.dae" />
				</geometry>
				<material name="Schunk_Black">
					<color rgba="0.0 0.0 0.0 1.0"/>
				</material>
			</visual>
			
			<collision>
				<origin xyz="0 0 0" rpy="0 0 0" />
				<geometry>
					<mesh filename="package://apc_ros/data/models/lwa4d/meshes/arm_6_link.dae"/>
				</geometry>
			</collision>
		</link>

		<!-- J7-->
		<joint name="L7_joint" type="revolute">
			<origin xyz="0 -0.075 0" rpy="-1.57 0 0" />
			<parent link="L6_link"/>
			<child link="L7_link"/>
			<axis xyz="0 0 1" />
			<dynamics damping="5" />
			<limit effort="9.6" velocity="2.0" lower="-6.2831853" upper="6.2831853" />
		</joint>

		<!-- L7-->
		<link name="L7_link">
			<inertial>
				<origin xyz="0 0 0" rpy="0 0 0"/>
				<mass value="1.120198"/>
				<inertia ixx="0.01" ixy="0" ixz="0" iyy="0.01" iyz="0" izz="0.01" />
			</inertial>
			
			<visual>
				<origin xyz="0 0 0" rpy="0 0 0" />
				<geometry>
					<mesh filename="package://apc_ros/data/models/lwa4d/meshes/arm_7_link.dae" />
				</geometry>
				<material name="Schunk_LightGrey" />
			</visual>
			
			<collision>
				<origin xyz="0 0 0" rpy="0 0 0" />
				<geometry>
					<mesh filename="package://apc_ros/data/models/lwa4d/meshes/arm_7_link.dae"/>
				</geometry>
			</collision>
		</link>

		<!-- joint between L7_link and sdh_palm_link -->
		<joint name="palm_joint" type="fixed" >?
			<origin xyz="0 0 -0.00" rpy="0 3.1416 0"/>
			<parent link="L7_link" />
			<child link="palm_link" />
		</joint>

		<link name="palm_link">
			<inertial>
				<origin xyz="0 0 0" rpy="0 0 0"/>
				<mass value="1"/>
				<inertia ixx="0.01" ixy="0" ixz="0" iyy="0.01" iyz="0" izz="0.01" />
			</inertial>
			
			<visual>
				<origin xyz="0 0 0" rpy="0 0 0" />
				<geometry>
					<mesh filename="package://apc_ros/data/models/sdh/meshes/palm.dae" />
				</geometry>
				<material name="Schunk_LightGrey">
					<color rgba="0.7 0.7 0.7 1.0"/>
				</material>
			</visual>
			
			<collision>
				<origin xyz="0 0 0" rpy="0 0 0" />
				<geometry>
					<mesh filename="package://apc_ros/data/models/sdh/meshes/palm.dae"/>
				</geometry>
			</collision>
		</link>
		
		<!-- grasp link -->
		<joint name="grasp_joint" type="fixed" >
			<origin xyz="0 0 0.15" rpy="0 0 0"/>
			<parent link="palm_link" />
			<child link="grasp_link" />
		</joint>

		<link name="grasp_link"/>

		<!-- tip link -->
		<joint name="tip_joint" type="fixed" >
			<origin xyz="0 0 0.22" rpy="0 0 0"/>
			<parent link="palm_link" />
			<child link="tip_link" />
		</joint>

		<link name="tip_link"/>

		<!-- finger1 -->
		<!-- joint between sdh_palm_link and sdh_finger_11_link -->
		<joint name="knuckle_joint" type="revolute">
			<origin xyz=" 0.033 -0.01905 0.0745" rpy="0 0 1.5708" />
			<parent link="palm_link"/>
			<child link="finger_11_link"/>
			<axis xyz="0 0 1" />
			<dynamics damping="1" />
			<limit effort="100" lower="0" upper="1.570796327" velocity="5"/>
		</joint>

		<link name="finger_11_link">
			<inertial>
				<origin xyz="0 0 0" rpy="0 0 0"/>
				<mass value="0.1"/>
				<inertia ixx="0.01" ixy="0" ixz="0" iyy="0.01" iyz="0" izz="0.01" />
			</inertial>
			
			<visual>
				<origin xyz="0 0 0" rpy="0 0 0" />
				<geometry>
					<mesh filename="package://apc_ros/data/models/sdh/meshes/knuckle.dae" />
				</geometry>
				<material name="Schunk_LightGrey" />
			</visual>
			
			<collision>
				<origin xyz="0 0 0" rpy="0 0 0" />
				<geometry>
				<mesh filename="package://apc_ros/data/models/sdh/meshes/knuckle.dae"/>
				</geometry>
			</collision>
		</link>

		<!-- joint between sdh_finger_11_link and sdh_finger_12_link -->
		<joint name="finger_12_joint" type="revolute">
			<origin xyz="0 0 0.0165" rpy="0 0 0" />
			<parent link="finger_11_link"/>
			<child link="finger_12_link"/>
			<axis xyz="0 1 0" />
			<dynamics damping="1" />
			<limit effort="100" lower="-1.570796327" upper="1.570796327" velocity="5"/>
		</joint>

		<link name="finger_12_link">
			<inertial>
				<origin xyz="0 0 0" rpy="0 0 0"/>
				<mass value="0.1"/>
				<inertia ixx="0.01" ixy="0" ixz="0" iyy="0.01" iyz="0" izz="0.01" />
			</inertial>
			
			<visual>
				<origin xyz="0 0 0" rpy="0 0 0" />
				<geometry>
					<mesh filename="package://apc_ros/data/models/sdh/meshes/finger.dae" />
				</geometry>
			<material name="Schunk_LightGrey" />
			</visual>
			
			<collision>
				<origin xyz="0 0 0" rpy="0 0 0" />
				<geometry>
					<mesh filename="package://apc_ros/data/models/sdh/meshes/finger.dae"/>
				</geometry>
			</collision>
		</link>

		<!-- joint between sdh_finger_12_link and sdh_finger_13_link -->
		<joint name="finger_13_joint" type="revolute">
			 
			<origin xyz="0 0 0.0865" rpy="0 0 0" />
			<parent link="finger_12_link"/>
			<child link="finger_13_link"/>
			<axis xyz="0 1 0" />
			<dynamics damping="1" />
			<limit effort="100" lower="-1.570796327" upper="1.570796327" velocity="5"/>
		</joint>

		<link name="finger_13_link">
			<inertial>
			<origin xyz="0 0 0" rpy="0 0 0"/>
				<mass value="0.1"/>
				<inertia ixx="0.01" ixy="0" ixz="0" iyy="0.01" iyz="0" izz="0.01" />
			</inertial>
			
			<visual>
				<origin xyz="0 0 0" rpy="0 0 0" />
				<geometry>
					<mesh filename="package://apc_ros/data/models/sdh/meshes/finger_tip.dae" />
				</geometry>
				<material name="Schunk_LightGrey" />
			</visual>
			
			<collision>
				<origin xyz="0 0 0" rpy="0 0 0" />
				<geometry>
					<mesh filename="package://apc_ros/data/models/sdh/meshes/finger_tip.dae"/>
				</geometry>
			</collision>
		</link>

		<!-- finger2 -->
		<!-- joint between sdh_palm_link and sdh_finger_21_link -->
		<joint name="finger_21_joint" type="revolute">
			<mimic joint="knuckle_joint" multiplier="1" offset="0"/>
			<origin xyz="-0.033 -0.01905 0.0745" rpy="0 0 1.5708" />
			<parent link="palm_link"/>
			<child link="finger_21_link"/>
			<axis xyz="0 0 -1" />
			<dynamics damping="1" />
			<limit effort="100" lower="0" upper="1.570796327" velocity="5"/>
		</joint>

		<link name="finger_21_link">
			<inertial>
				<origin xyz="0 0 0" rpy="0 0 0"/>
				<mass value="0.1"/>
				<inertia ixx="0.01" ixy="0" ixz="0" iyy="0.01" iyz="0" izz="0.01" />
			</inertial>
			
			<visual>
				<origin xyz="0 0 0" rpy="0 0 0" />
				<geometry>
					<mesh filename="package://apc_ros/data/models/sdh/meshes/knuckle.dae" />
				</geometry>
				<material name="Schunk_LightGrey" />
			</visual>
			
			<collision>
				<origin xyz="0 0 0" rpy="0 0 0" />
				<geometry>
					<mesh filename="package://apc_ros/data/models/sdh/meshes/knuckle.dae"/>
				</geometry>
			</collision>
		</link>

		<!-- joint between sdh_finger_21_link and sdh_finger_22_link -->
		<joint name="finger_22_joint" type="revolute">
			<origin xyz="0 0 0.0165" rpy="0 0 0" />
			<parent link="finger_21_link"/>
			<child link="finger_22_link"/>
			<axis xyz="0 1 0" />
			<dynamics damping="1" />
			<limit effort="100" lower="-1.570796327" upper="1.570796327" velocity="5"/>
		</joint>

		<link name="finger_22_link">
			<inertial>
				<origin xyz="0 0 0" rpy="0 0 0"/>
				<mass value="0.1"/>
				<inertia ixx="0.01" ixy="0" ixz="0" iyy="0.01" iyz="0" izz="0.01" />
			</inertial>
			
			<visual>
				<origin xyz="0 0 0" rpy="0 0 0" />
				<geometry>
					<mesh filename="package://apc_ros/data/models/sdh/meshes/finger.dae" />
				</geometry>
				<material name="Schunk_LightGrey" />
			</visual>
			
			<collision>
				<origin xyz="0 0 0" rpy="0 0 0" />
				<geometry>
					<mesh filename="package://apc_ros/data/models/sdh/meshes/finger.dae"/>
				</geometry>
			</collision>
		</link>

		<!-- joint between sdh_finger_22_link and sdh_finger_23_link -->
		<joint name="finger_23_joint" type="revolute">
			<origin xyz="0 0 0.0865" rpy="0 0 0" />
			<parent link="finger_22_link"/>
			<child link="finger_23_link"/>
			<axis xyz="0 1 0" />
			<dynamics damping="1" />
			<limit effort="100" lower="-1.570796327" upper="1.570796327" velocity="5"/>
		</joint>

		<link name="finger_23_link">
			<inertial>
				<origin xyz="0 0 0" rpy="0 0 0"/>
				<mass value="0.1"/>
				<inertia ixx="0.01" ixy="0" ixz="0" iyy="0.01" iyz="0" izz="0.01" />
			</inertial>
			
			<visual>
				<origin xyz="0 0 0" rpy="0 0 0" />
				<geometry>
					<mesh filename="package://apc_ros/data/models/sdh/meshes/finger_tip.dae" />
				</geometry>
				<material name="Schunk_LightGrey" />
			</visual>
			
			<collision>
				<origin xyz="0 0 0" rpy="0 0 0" />
				<geometry>
					<mesh filename="package://apc_ros/data/models/sdh/meshes/finger_tip.dae"/>
				</geometry>
			</collision>
		</link>

		<!-- thumb -->
		<!-- joint between sdh_palm_link and sdh_thumb_1_link -->
		<joint name="thumb_1_joint" type="fixed">
			<origin xyz="0.0 0.03811 0.0745 " rpy="0 0 -1.5708" />
			<parent link="palm_link"/>
			<child link="thumb_1_link"/>
		</joint>

		<link name="thumb_1_link">
			<inertial>
				<origin xyz="0 0 0" rpy="0 0 0"/>
				<mass value="0.1"/>
				<inertia ixx="0.01" ixy="0" ixz="0" iyy="0.01" iyz="0" izz="0.01" />
			</inertial>
			
			<visual>
				<origin xyz="0 0 0" rpy="0 0 0" />
				<geometry>
					<mesh filename="package://apc_ros/data/models/sdh/meshes/knuckle.dae" />
				</geometry>
				<material name="Schunk_LightGrey" />
			</visual>
			
			<collision>
				<origin xyz="0 0 0" rpy="0 0 0" />
				<geometry>
					<mesh filename="package://apc_ros/data/models/sdh/meshes/knuckle.dae"/>
				</geometry>
			</collision>
		</link>

		<!-- joint between sdh_thumb_1_link and shd_thumb_2_link -->
		<joint name="thumb_2_joint" type="revolute">
		<origin xyz="0 0 0.0165" rpy="0 0 0" />
		<parent link="thumb_1_link"/>
		<child link="thumb_2_link"/>
		<axis xyz="0 1 0" />
		<dynamics damping="1" />
		<limit effort="100" lower="-1.570796327" upper="1.570796327" velocity="5"/>
		</joint>

		<link name="thumb_2_link">
			<inertial>
				<origin xyz="0 0 0" rpy="0 0 0"/>
				<mass value="0.1"/>	
				<inertia ixx="0.01" ixy="0" ixz="0" iyy="0.01" iyz="0" izz="0.01" />
			</inertial>
		
			<visual>
				<origin xyz="0 0 0" rpy="0 0 0" />
				<geometry>
					<mesh filename="package://apc_ros/data/models/sdh/meshes/finger.dae" />
				</geometry>
				<material name="Schunk_LightGrey" />
			</visual>
		
			<collision>
				<origin xyz="0 0 0" rpy="0 0 0" />
				<geometry>
					<mesh filename="package://apc_ros/data/models/sdh/meshes/finger.dae"/>
				</geometry>
			</collision>
		</link>

		<!-- joint between sdh_thumb_2_link and sdh_thumb_3_link -->
		<joint name="thumb_3_joint" type="revolute">
			<origin xyz="0 0 0.0865" rpy="0 0 0" />
			<parent link="thumb_2_link"/>
			<child link="thumb_3_link"/>
			<axis xyz="0 1 0" />
			<dynamics damping="1" />
			<limit effort="100" lower="-1.570796327" upper="1.570796327" velocity="5"/>
		</joint>

		<link name="thumb_3_link">
			<inertial>
				<origin xyz="0 0 0" rpy="0 0 0"/>
				<mass value="0.1"/>
				<inertia ixx="0.01" ixy="0" ixz="0" iyy="0.01" iyz="0" izz="0.01" />
			</inertial>
			
			<visual>
				<origin xyz="0 0 0" rpy="0 0 0" />
				<geometry>
					<mesh filename="package://apc_ros/data/models/sdh/meshes/finger_tip.dae" />
				</geometry>
				<material name="Schunk_LightGrey" />
			</visual>
			
			<collision>
				<origin xyz="0 0 0" rpy="0 0 0" />
				<geometry>
					<mesh filename="package://apc_ros/data/models/sdh/meshes/finger_tip.dae"/>
				</geometry>
			</collision>
		</link>

</robot>
